
An error occurred (InternalFailure) when calling the Invoke operation (reached max retries: 4): Error executing Lambda function arn:aws:lambda:us-east-1:000000000000:function:ProlambBadCallable: Lambda process returned error status code: 1. Output:
[32mSTART RequestId: 9ff5450d-5f10-1594-dc26-d9e1a877fa90 Version: $LATEST[0m
[32mEND RequestId: 9ff5450d-5f10-1594-dc26-d9e1a877fa90[0m
[32mREPORT RequestId: 9ff5450d-5f10-1594-dc26-d9e1a877fa90	Init Duration: 390.20 ms	Duration: 0.00 ms	Billed Duration: 100 ms	Memory Size: 1536 MB	Max Memory Used: 15 MB	[0m
[31m{
  "errorType": "InvalidHandlerCallable",
  "errorMessage": "Could not find callable named 'hand'"
}[0m Traceback (most recent call last):
  File "/opt/code/localstack/localstack/services/awslambda/lambda_api.py", line 338, in run_lambda
    event, context=context, version=version, asynchronous=asynchronous)
  File "/opt/code/localstack/localstack/services/awslambda/lambda_executors.py", line 83, in execute
    return do_execute()
  File "/opt/code/localstack/localstack/services/awslambda/lambda_executors.py", line 68, in do_execute
    result, log_output = self._execute(func_arn, func_details, event, context, version)
  File "/opt/code/localstack/localstack/services/awslambda/lambda_executors.py", line 229, in _execute
    result, log_output = self.run_lambda_executor(cmd, stdin, environment)
  File "/opt/code/localstack/localstack/services/awslambda/lambda_executors.py", line 149, in run_lambda_executor
    (return_code, log_output))
Exception: Lambda process returned error status code: 1. Output:
[32mSTART RequestId: 9ff5450d-5f10-1594-dc26-d9e1a877fa90 Version: $LATEST[0m
[32mEND RequestId: 9ff5450d-5f10-1594-dc26-d9e1a877fa90[0m
[32mREPORT RequestId: 9ff5450d-5f10-1594-dc26-d9e1a877fa90	Init Duration: 390.20 ms	Duration: 0.00 ms	Billed Duration: 100 ms	Memory Size: 1536 MB	Max Memory Used: 15 MB	[0m
[31m{
  "errorType": "InvalidHandlerCallable",
  "errorMessage": "Could not find callable named 'hand'"
}[0m

